Workbook
Name Alarm: options!$A$2:$A$3
Name BILLINGFREQ: [1]Tables!$C$1:$C$7
Name Customers: '[1]Customer Table'!$B$1:$B$1116
Name JOBTYPES: [1]Tables!$O$1:$O$6
Name SALESPERSON: [1]Tables!$E$1:$E$21

Sheet Totals
B1: ESTIMATING SHEET VERSION 8.6 | G1: Salesman: | I1: 40 VA | L1: Add Date Below
B2: Job Name: | G2: Estimator:
B3: Part Number | D3: QTY. | E3: MATERIAL DESCRIPTON | H3: LIST $ | J3: # of Contrs | K3: # of Points | M3: TOTAL | R3: Electrical Price Check | V3: Tech | Z3: Graphics | AD3: Programming
Q5: TOTAL | R5: ='Base Estimate'!R482+'Estimate 2'!R482+'Estimate 3'!R482+'Estimate 4'!R482+'Estimate 5'!R482+'Estimate 6'!R482+'Estimate 7'!R482+'Estimate 8'!R482+'Estimate 9'!R482+'Estimate 10'!R482 -> 0 | S5: Install | V5: ='Base Estimate'!V482+'Estimate 2'!V482+'Estimate 3'!V482+'Estimate 4'!V482+'Estimate 5'!V482+'Estimate 6'!V482+'Estimate 7'!V482+'Estimate 8'!V482+'Estimate 9'!V482+'Estimate 10'!V482 -> 0 | W5: Tech Hours | Z5: ='Base Estimate'!Z482+'Estimate 2'!Z482+'Estimate 3'!Z482+'Estimate 4'!Z482+'Estimate 5'!Z482+'Estimate 6'!Z482+'Estimate 7'!Z482+'Estimate 8'!Z482+'Estimate 9'!Z482+'Estimate 10'!Z482 -> 0 | AA5: Graphic Hours | AD5: ='Base Estimate'!AD482+'Estimate 2'!AD482+'Estimate 3'!AD482+'Estimate 4'!AD482+'Estimate 5'!AD482+'Estimate 6'!AD482+'Estimate 7'!AD482+'Estimate 8'!AD482+'Estimate 9'!AD482+'Estimate 10'!AD482 -> 0 | AE5: Programming Hours
J6: =D5+D7 -> 0 | K6: =J6*50 -> 0
R7: ='Base Estimate'!R484+'Estimate 2'!R484+'Estimate 3'!R484+'Estimate 4'!R484+'Estimate 5'!R484+'Estimate 6'!R484+'Estimate 7'!R484+'Estimate 8'!R484+'Estimate 9'!R484+'Estimate 10'!R484 -> 0 | S7: ='Base Estimate'!S484 -> 0
I8: SUB TOTAL | J8: ='Base Estimate'!J485+'Estimate 2'!J485+'Estimate 3'!J485+'Estimate 4'!J485+'Estimate 5'!J485+'Estimate 6'!J485+'Estimate 7'!J485+'Estimate 8'!J485+'Estimate 9'!J485+'Estimate 10'!J485 -> 0 | M8: ='Base Estimate'!M485+'Estimate 2'!M485+'Estimate 3'!M485+'Estimate 4'!M485+'Estimate 5'!M485+'Estimate 6'!M485+'Estimate 7'!M485+'Estimate 8'!M485+'Estimate 9'!M485+'Estimate 10'!M485 -> 0 | R8: ='Base Estimate'!R485+'Estimate 2'!R485+'Estimate 3'!R485+'Estimate 4'!R485+'Estimate 5'!R485+'Estimate 6'!R485+'Estimate 7'!R485+'Estimate 8'!R485+'Estimate 9'!R485+'Estimate 10'!R485 -> 0 | S8: ='Base Estimate'!S485 -> 0
I9: TAX | J9: ='Base Estimate'!J486+'Estimate 2'!J486+'Estimate 3'!J486+'Estimate 4'!J486+'Estimate 5'!J486+'Estimate 6'!J486+'Estimate 7'!J486+'Estimate 8'!J486+'Estimate 9'!J486+'Estimate 10'!J486 -> 0 | L9: ='Base Estimate'!L486 -> 0.0825 | M9: ='Base Estimate'!M486+'Estimate 2'!M486+'Estimate 3'!M486+'Estimate 4'!M486+'Estimate 5'!M486+'Estimate 6'!M486+'Estimate 7'!M486+'Estimate 8'!M486+'Estimate 9'!M486+'Estimate 10'!M486 -> 0 | R9: ='Base Estimate'!R486+'Estimate 2'!R486+'Estimate 3'!R486+'Estimate 4'!R486+'Estimate 5'!R486+'Estimate 6'!R486+'Estimate 7'!R486+'Estimate 8'!R486+'Estimate 9'!R486+'Estimate 10'!R486 -> 0 | S9: ='Base Estimate'!S486 -> 0
I10: FREIGHT | J10: ='Base Estimate'!J487+'Estimate 2'!J487+'Estimate 3'!J487+'Estimate 4'!J487+'Estimate 5'!J487+'Estimate 6'!J487+'Estimate 7'!J487+'Estimate 8'!J487+'Estimate 9'!J487+'Estimate 10'!J487 -> 0 | L10: 0.07 | M10: ='Base Estimate'!M487+'Estimate 2'!M487+'Estimate 3'!M487+'Estimate 4'!M487+'Estimate 5'!M487+'Estimate 6'!M487+'Estimate 7'!M487+'Estimate 8'!M487+'Estimate 9'!M487+'Estimate 10'!M487 -> 0 | R10: ='Base Estimate'!R487+'Estimate 2'!R487+'Estimate 3'!R487+'Estimate 4'!R487+'Estimate 5'!R487+'Estimate 6'!R487+'Estimate 7'!R487+'Estimate 8'!R487+'Estimate 9'!R487+'Estimate 10'!R487 -> 0 | S10: ='Base Estimate'!S487 -> 0
I11: TOTAL W/TAX | J11: ='Base Estimate'!J488+'Estimate 2'!J488+'Estimate 3'!J488+'Estimate 4'!J488+'Estimate 5'!J488+'Estimate 6'!J488+'Estimate 7'!J488+'Estimate 8'!J488+'Estimate 9'!J488+'Estimate 10'!J488 -> 0 | M11: ='Base Estimate'!M488+'Estimate 2'!M488+'Estimate 3'!M488+'Estimate 4'!M488+'Estimate 5'!M488+'Estimate 6'!M488+'Estimate 7'!M488+'Estimate 8'!M488+'Estimate 9'!M488+'Estimate 10'!M488 -> 0 | R11: {=MIN(IF(R7:R10>0,R7:R10))} -> 0
R12: =((R5-R13)/G23)*0.833 -> 0 | S12: Comparative labor hours @ burden rate based on the Total cost above
R13: =ROUND((R5*0.15)/1.1125,0) -> 0 | S13: This is 15% of the Total install dollars above to be used in no sub is chosen
B14: HOURS - CAL | C14: HOURS - ACT | D14: TITLE | G14: COST/HR | H14: TOTAL
B15: =ROUND(V32,0) -> 0 | C15: ='Base Estimate'!A492+'Estimate 2'!A492+'Estimate 3'!A492+'Estimate 4'!A492+'Estimate 5'!A492+'Estimate 6'!A492+'Estimate 7'!A492+'Estimate 8'!A492+'Estimate 9'!A492+'Estimate 10'!A492 -> 0 | D15: TECH PROGRAMMING | G15: 74 | H15: =C15*G15 -> 0 | J15: =H15 -> 0 | Q15: Tech, Engineering and PM Hours | X15: Travel Expenses | AD15: Parking Cost - Tech + Install
B16: =V31 -> 0 | C16: ='Base Estimate'!A493+'Estimate 2'!A493+'Estimate 3'!A493+'Estimate 4'!A493+'Estimate 5'!A493+'Estimate 6'!A493+'Estimate 7'!A493+'Estimate 8'!A493+'Estimate 9'!A493+'Estimate 10'!A493 -> 0 | D16: SENIOR TECHNICAL PROGRAMMING | G16: 101 | H16: =C16*G16 -> 0 | J16: =H16 -> 0
B17: =ROUND(V19,0) -> 0 | C17: ='Base Estimate'!A494+'Estimate 2'!A494+'Estimate 3'!A494+'Estimate 4'!A494+'Estimate 5'!A494+'Estimate 6'!A494+'Estimate 7'!A494+'Estimate 8'!A494+'Estimate 9'!A494+'Estimate 10'!A494 -> 0 | D17: GRAPHICS | G17: 74 | H17: =C17*G17 -> 0 | J17: =H17 -> 0 | Q17: Tech Training Hours | V17: ='Base Estimate'!V495+'Estimate 2'!V495+'Estimate 3'!V495+'Estimate 4'!V495+'Estimate 5'!V495+'Estimate 6'!V495+'Estimate 7'!V495+'Estimate 8'!V495+'Estimate 9'!V495+'Estimate 10'!V495 -> 0 | X17: Tech/Install Hotel | AA17: 0 | AD17: Cost Per Day | AG17: 0
B18: =V35 -> 0 | C18: ='Base Estimate'!A495+'Estimate 2'!A495+'Estimate 3'!A495+'Estimate 4'!A495+'Estimate 5'!A495+'Estimate 6'!A495+'Estimate 7'!A495+'Estimate 8'!A495+'Estimate 9'!A495+'Estimate 10'!A495 -> 0 | D18: ENGINEERING | G18: 102 | H18: =C18*G18 -> 0 | J18: =H18 -> 0 | N18: =C19+C17+C16+C15 -> 0 | O18: Tech+Graphics
B19: =V29 -> 0 | C19: ='Base Estimate'!A496+'Estimate 2'!A496+'Estimate 3'!A496+'Estimate 4'!A496+'Estimate 5'!A496+'Estimate 6'!A496+'Estimate 7'!A496+'Estimate 8'!A496+'Estimate 9'!A496+'Estimate 10'!A496 -> 0 | D19: TECHNICAL | G19: 74 | H19: =C19*G19 -> 0 | J19: =H19 -> 0 | O19: Programming | Q19: Graphics Hours | V19: =Z5 -> 0 | X19: Tech/Install Per Diem | AA19: 0 | AD19: Days Parked | AG19: =ROUNDUP((((V5+V17+V21+V23+C23)/40)*5),0) -> 0
B20: =ROUND(V38,0) -> 0 | C20: ='Base Estimate'!A497+'Estimate 2'!A497+'Estimate 3'!A497+'Estimate 4'!A497+'Estimate 5'!A497+'Estimate 6'!A497+'Estimate 7'!A497+'Estimate 8'!A497+'Estimate 9'!A497+'Estimate 10'!A497 -> 0 | D20: SENIOR PROJECT MANAGER | G20: 134 | H20: =C20*G20 -> 0 | J20: =H20 -> 0
B21: =ROUND(V39,0) -> 0 | C21: ='Base Estimate'!A498+'Estimate 2'!A498+'Estimate 3'!A498+'Estimate 4'!A498+'Estimate 5'!A498+'Estimate 6'!A498+'Estimate 7'!A498+'Estimate 8'!A498+'Estimate 9'!A498+'Estimate 10'!A498 -> 0 | D21: ASSISTANT PROJECT MANAGER | G21: 75 | H21: =C21*G21 -> 0 | J21: =H21 -> 0 | Q21: Add Tech Comm,Travel, TAB Hrs | V21: ='Base Estimate'!V499+'Estimate 2'!V499+'Estimate 3'!V499+'Estimate 4'!V499+'Estimate 5'!V499+'Estimate 6'!V499+'Estimate 7'!V499+'Estimate 8'!V499+'Estimate 9'!V499+'Estimate 10'!V499 -> 0 | X21: Tech/Install Days | AA21: =ROUNDUP((((V5+V17+V21+V23+V25+C23)/40)*5),0) -> 0
C22: ='Base Estimate'!C499+'Estimate 2'!C499+'Estimate 3'!C499+'Estimate 4'!C499+'Estimate 5'!C499+'Estimate 6'!C499+'Estimate 7'!C499+'Estimate 8'!C499+'Estimate 9'!C499+'Estimate 10'!C499 -> 0 | D22: ELECTRICAL ASSISTANT - Panel Building | G22: 58 | H22: =C22*G22 -> 0 | J22: =H22 -> 0 | X22: Out of Town | AD22: Total Parking Cost | AG22: ='Base Estimate'!AG500+'Estimate 2'!AG499+'Estimate 3'!AG499+'Estimate 4'!AG499+'Estimate 5'!AG499+'Estimate 6'!AG499+'Estimate 7'!AG499+'Estimate 8'!AG499+'Estimate 9'!AG499+'Estimate 10'!AG499 -> 0
C23: ='Base Estimate'!C500+'Estimate 2'!C500+'Estimate 3'!C500+'Estimate 4'!C500+'Estimate 5'!C500+'Estimate 6'!C500+'Estimate 7'!C500+'Estimate 8'!C500+'Estimate 9'!C500+'Estimate 10'!C500 -> 0 | D23: ELECTRICAL INSTALLER | G23: 58 | H23: =C23*G23 -> 0 | J23: =H23 -> 0 | Q23: Add Phasing, High Rise, etc | V23: ='Base Estimate'!V501+'Estimate 2'!V501+'Estimate 3'!V501+'Estimate 4'!V501+'Estimate 5'!V501+'Estimate 6'!V501+'Estimate 7'!V501+'Estimate 8'!V501+'Estimate 9'!V501+'Estimate 10'!V501 -> 0
D24: TOTAL LABOR COST | H24: =SUM(H15:H23) -> 0 | I24: =IFERROR((M24-H24)/(M24),0.32) -> 0.32 | J24: =SUM(J15:J23) -> 0 | M24: ='Base Estimate'!M501+'Estimate 2'!M501+'Estimate 3'!M501+'Estimate 4'!M501+'Estimate 5'!M501+'Estimate 6'!M501+'Estimate 7'!M501+'Estimate 8'!M501+'Estimate 9'!M501+'Estimate 10'!M501 -> 0 | N24: =IFERROR(H24/H35,"0") -> 0 | O24: MTC w Local Labor | X24: Tech/Install Travel | AA24: ='Base Estimate'!AA502+'Estimate 2'!AA501+'Estimate 3'!AA501+'Estimate 4'!AA501+'Estimate 5'!AA501+'Estimate 6'!AA501+'Estimate 7'!AA501+'Estimate 8'!AA501+'Estimate 9'!AA501+'Estimate 10'!AA501 -> 0
Q25: Add Tech Travel Time | V25: ='Base Estimate'!V503+'Estimate 2'!V503+'Estimate 3'!V503+'Estimate 4'!V503+'Estimate 5'!V503+'Estimate 6'!V503+'Estimate 7'!V503+'Estimate 8'!V503+'Estimate 9'!V503+'Estimate 10'!V503 -> 0 | X25: Cost
D26: MATERIALS & TRIP | N26: =IFERROR(J24/J35,"0") -> 0 | O26: MTC w Sub Labor | Q26: Estimated travel time to site = | T26: 0 | U26: hrs
D27: MILEAGE - ROUND TRIP | G27: 100 | H27: ='Base Estimate'!H504+'Estimate 2'!H504+'Estimate 3'!H504+'Estimate 4'!H504+'Estimate 5'!H504+'Estimate 6'!H504+'Estimate 7'!H504+'Estimate 8'!H504+'Estimate 9'!H504+'Estimate 10'!H504 -> 0 | I27: =IFERROR((M27-H27)/(M27),0.32) -> 0.32 | J27: =IF(G27<=100,(C18+(C20/3))/8*(50),IF(G27>100,(C18+ (C20/3))/8*(G27)*0.5)) -> 0 | M27: ='Base Estimate'!M504+'Estimate 2'!M504+'Estimate 3'!M504+'Estimate 4'!M504+'Estimate 5'!M504+'Estimate 6'!M504+'Estimate 7'!M504+'Estimate 8'!M504+'Estimate 9'!M504+'Estimate 10'!M504 -> 0 | AD27: Mechanical Labor
D28: MATERIALS | H28: ='Base Estimate'!H505+'Estimate 2'!H505+'Estimate 3'!H505+'Estimate 4'!H505+'Estimate 5'!H505+'Estimate 6'!H505+'Estimate 7'!H505+'Estimate 8'!H505+'Estimate 9'!H505+'Estimate 10'!H505 -> 0 | I28: =IFERROR((M28-H28)/(M28),0.32) -> 0.32 | J28: =J11 -> 0 | M28: ='Base Estimate'!M505+'Estimate 2'!M505+'Estimate 3'!M505+'Estimate 4'!M505+'Estimate 5'!M505+'Estimate 6'!M505+'Estimate 7'!M505+'Estimate 8'!M505+'Estimate 9'!M505+'Estimate 10'!M505 -> 0
D29: SUB | H29: ='Base Estimate'!H506+'Estimate 2'!H506+'Estimate 3'!H506+'Estimate 4'!H506+'Estimate 5'!H506+'Estimate 6'!H506+'Estimate 7'!H506+'Estimate 8'!H506+'Estimate 9'!H506+'Estimate 10'!H506 -> 0 | I29: =IFERROR((M29-H29)/(M29),0.32) -> 0.32 | J29: =R5 -> 0 | M29: ='Base Estimate'!M506+'Estimate 2'!M506+'Estimate 3'!M506+'Estimate 4'!M506+'Estimate 5'!M506+'Estimate 6'!M506+'Estimate 7'!M506+'Estimate 8'!M506+'Estimate 9'!M506+'Estimate 10'!M506 -> 0 | Q29: Total Tech Hours (Less Graphics) | V29: =V5+V17+V21+V23+V25 -> 0 | X29: PM Hotel | AA29: 0 | AD29: Total Mechanical Labor | AG29: ='Base Estimate'!AG508+'Estimate 2'!AG506+'Estimate 3'!AG506+'Estimate 4'!AG506+'Estimate 5'!AG506+'Estimate 6'!AG506+'Estimate 7'!AG506+'Estimate 8'!AG506+'Estimate 9'!AG506+'Estimate 10'!AG506 -> 0
D30: INTEGRATION/CONTINENCY/OTHER | H30: ='Base Estimate'!H507+'Estimate 2'!H507+'Estimate 3'!H507+'Estimate 4'!H507+'Estimate 5'!H507+'Estimate 6'!H507+'Estimate 7'!H507+'Estimate 8'!H507+'Estimate 9'!H507+'Estimate 10'!H507 -> 0 | I30: =IFERROR((M30-H30)/(M30),0.32) -> 0.32 | J30: =H30 -> 0 | M30: ='Base Estimate'!M507+'Estimate 2'!M507+'Estimate 3'!M507+'Estimate 4'!M507+'Estimate 5'!M507+'Estimate 6'!M507+'Estimate 7'!M507+'Estimate 8'!M507+'Estimate 9'!M507+'Estimate 10'!M507 -> 0
D31: HOTEL/PER DIEM/AIRFARE/CAR/PARKING | H31: ='Base Estimate'!H508+'Estimate 2'!H508+'Estimate 3'!H508+'Estimate 4'!H508+'Estimate 5'!H508+'Estimate 6'!H508+'Estimate 7'!H508+'Estimate 8'!H508+'Estimate 9'!H508+'Estimate 10'!H508 -> 0 | I31: =IFERROR((M31-H31)/(M31),0.32) -> 0.32 | J31: =H31 -> 0 | M31: ='Base Estimate'!M508+'Estimate 2'!M508+'Estimate 3'!M508+'Estimate 4'!M508+'Estimate 5'!M508+'Estimate 6'!M508+'Estimate 7'!M508+'Estimate 8'!M508+'Estimate 9'!M508+'Estimate 10'!M508 -> 0 | Q31: =IFERROR((V31/(V31+V32)),0) -> 0 | R31: Hours for Senior Tech | V31: ='Base Estimate'!V509+'Estimate 2'!V509+'Estimate 3'!V509+'Estimate 4'!V509+'Estimate 5'!V509+'Estimate 6'!V509+'Estimate 7'!V509+'Estimate 8'!V509+'Estimate 9'!V509+'Estimate 10'!V509 -> 0
D32: CONTINGENCY | H32: ='Base Estimate'!H509+'Estimate 2'!H509+'Estimate 3'!H509+'Estimate 4'!H509+'Estimate 5'!H509+'Estimate 6'!H509+'Estimate 7'!H509+'Estimate 8'!H509+'Estimate 9'!H509+'Estimate 10'!H509 -> 0 | I32: =IFERROR((M32-H32)/(M32),0.32) -> 0.32 | J32: =H32 -> 0 | M32: ='Base Estimate'!M509+'Estimate 2'!M509+'Estimate 3'!M509+'Estimate 4'!M509+'Estimate 5'!M509+'Estimate 6'!M509+'Estimate 7'!M509+'Estimate 8'!M509+'Estimate 9'!M509+'Estimate 10'!M509 -> 0 | Q32: =IFERROR((V32/(V31+V32)),0) -> 0 | R32: Hours for Tech | V32: ='Base Estimate'!V510+'Estimate 2'!V510+'Estimate 3'!V510+'Estimate 4'!V510+'Estimate 5'!V510+'Estimate 6'!V510+'Estimate 7'!V510+'Estimate 8'!V510+'Estimate 9'!V510+'Estimate 10'!V510 -> 0 | X32: PM Per Diem | AA32: 0
D33: TOTAL MATERIALS & TRIP COST | H33: =SUM(H27:H32) -> 0 | J33: =SUM(J27:J32) -> 0
D35: JOB COST | H35: =H24+H33 -> 0 | J35: =J24+J33 -> 0 | Q35: Engineering x tech multiplier | T35: 0 | V35: ='Base Estimate'!V513+'Estimate 2'!V513+'Estimate 3'!V513+'Estimate 4'!V513+'Estimate 5'!V513+'Estimate 6'!V513+'Estimate 7'!V513+'Estimate 8'!V513+'Estimate 9'!V513+'Estimate 10'!V513 -> 0 | X35: PM Days out of Town | AA35: =ROUNDUP((((V41*V42)/40)*5),0) -> 0
D36: WARRANTY | G36: 0.02 | H36: ='Base Estimate'!H514+'Estimate 2'!H514+'Estimate 3'!H514+'Estimate 4'!H514+'Estimate 5'!H514+'Estimate 6'!H514+'Estimate 7'!H514+'Estimate 8'!H514+'Estimate 9'!H514+'Estimate 10'!H514 -> 0 | I36: =IFERROR((M36-H36)/(M36),0.32) -> 0.32 | M36: ='Base Estimate'!M514+'Estimate 2'!M514+'Estimate 3'!M514+'Estimate 4'!M514+'Estimate 5'!M514+'Estimate 6'!M514+'Estimate 7'!M514+'Estimate 8'!M514+'Estimate 9'!M514+'Estimate 10'!M514 -> 0
D37: MECHANICAL LABOR | H37: ='Base Estimate'!H515 -> 0 | M37: =AG29 -> 0
D38: SALES TAX (NC RMI ONLY) | F38: Mecklenburg, NC | G38: ='State Taxes'!E9 -> 0.0825 | M38: ='State Taxes'!E9 -> 0.0825 | Q38: =IFERROR((V38/(V38+V39)),0) -> 0 | R38: Hours for Senior PM | V38: ='Base Estimate'!V517+'Estimate 2'!V517+'Estimate 3'!V517+'Estimate 4'!V517+'Estimate 5'!V517+'Estimate 6'!V517+'Estimate 7'!V517+'Estimate 8'!V517+'Estimate 9'!V517+'Estimate 10'!V517 -> 0 | X38: PM Travel Cost | AA38: ='Base Estimate'!AA516+'Estimate 2'!AA514+'Estimate 3'!AA514+'Estimate 4'!AA514+'Estimate 5'!AA514+'Estimate 6'!AA514+'Estimate 7'!AA514+'Estimate 8'!AA514+'Estimate 9'!AA514+'Estimate 10'!AA514 -> 0
D39: Total Job Cost | H39: =H35+H36+H37+H38 -> 0 | Q39: =IFERROR((V39/(V38+V39)),0) -> 0 | R39: Hours for APM | V39: ='Base Estimate'!V518+'Estimate 2'!V518+'Estimate 3'!V518+'Estimate 4'!V518+'Estimate 5'!V518+'Estimate 6'!V518+'Estimate 7'!V518+'Estimate 8'!V518+'Estimate 9'!V518+'Estimate 10'!V518 -> 0
D40: JOB SALE PRICE | M40: ='Base Estimate'!M518+'Estimate 2'!M518+'Estimate 3'!M518+'Estimate 4'!M518+'Estimate 5'!M518+'Estimate 6'!M518+'Estimate 7'!M518+'Estimate 8'!M518+'Estimate 9'!M518+'Estimate 10'!M518 -> 0
Q41: Number of weeks of project | V41: 0 | X41: Car Allowance
I42: Margin | M42: =M40-H39 -> 0 | Q42: Hrs per week | V42: 0
...

Sheet Base Estimate
B1: =Totals!B1 -> ESTIMATING SHEET VERSION 8.6 | G1: Salesman: | H1: =Totals!H1 -> 0 | L1: 1 | N1: <- 1=Page Used, 0=Page not used
B2: Job Name: | C2: =Totals!C2 -> 0 | G2: Estimator: | H2: =Totals!H2 -> 0 | L2: =Totals!L2 -> 0
B3: Part Number | D3: QTY. | E3: MATERIAL DESCRIPTON | H3: LIST $ | J3: # of Contrs | K3: # of Points | M3: TOTAL | R3: Electrical Price Check | V3: Tech | Z3: Graphics | AD3: Programming
D5: 0 | E5: VAV Boxes w Heat | F5: Option | I5: #/unit | N5: 1 | O5: Pts/VAV | P5: =D5*N5 -> 0 | Q5: points | R5: =P5*S5 -> 0 | S5: 550 | T5: per VAV | V5: =P5*W5 -> 0 | W5: 1 | X5: per VAV | Z5: =P5*AA5 -> 0 | AA5: 0.25 | AB5: per VAV | AD5: =P5*AE5 -> 0 | AE5: 0.25 | AF5: per VAV
A6: =E6&F6 -> ControllerOptimizer BACnet MSTP VAV Cntr w Act & VP, Bluetooth, 7 UIO, 5 SSR | B6: =IF(E6="","",VLOOKUP(A6,'Parts List'!A:E,5,FALSE)) -> VAA-VA75MB24NMC | D6: =$D$5*I6 -> 0 | E6: Controller | F6: Optimizer BACnet MSTP VAV Cntr w Act & VP, Bluetooth, 7 UIO, 5 SSR | H6: =IF(E6="","",VLOOKUP(A6,'Parts List'!A:F,6,FALSE)) -> 281.3558 | I6: 1 | J6: =D6 -> 0 | K6: =D6*70 -> 0 | M6: =IF(H6="","",D6*H6) -> 0
A7: =E7&F7 -> Temp SensorTR100 Space with LCD | B7: =IF(E7="","",VLOOKUP(A7,'Parts List'!A:E,5,FALSE)) -> TR100-T-G | D7: =$D$5*I7 -> 0 | E7: Temp Sensor | F7: TR100 Space with LCD | H7: =IF(E7="","",VLOOKUP(A7,'Parts List'!A:F,6,FALSE)) -> 128.71265 | I7: 1 | M7: =IF(H7="","",D7*H7) -> 0
A8: =E8&F8 -> Temp SensorDuct Insertion Sensor | B8: =IF(E8="","",VLOOKUP(A8,'Parts List'!A:E,5,FALSE)) -> C7041B2005 | D8: =$D$5*I8 -> 0 | E8: Temp Sensor | F8: Duct Insertion Sensor | H8: =IF(E8="","",VLOOKUP(A8,'Parts List'!A:F,6,FALSE)) -> 23.18855 | I8: 1 | M8: =IF(H8="","",D8*H8) -> 0
A9: =E9&F9 -> Current SwDigital Status Switch | B9: =IF(E9="","",VLOOKUP(A9,'Parts List'!A:E,5,FALSE)) -> H600 | D9: =$D$5*I9 -> 0 | E9: Current Sw | F9: Digital Status Switch | H9: =IF(E9="","",VLOOKUP(A9,'Parts List'!A:F,6,FALSE)) -> 31.43 | I9: 0 | M9: =IF(H9="","",D9*H9) -> 0
A10: =E10&F10 -> RelayRIB Pilot Relay | B10: =IF(E10="","",VLOOKUP(A10,'Parts List'!A:E,5,FALSE)) -> RIBU1C | D10: =$D$5*I10 -> 0 | E10: Relay | F10: RIB Pilot Relay | H10: =IF(E10="","",VLOOKUP(A10,'Parts List'!A:F,6,FALSE)) -> 14.36 | I10: 0 | M10: =IF(H10="","",D10*H10) -> 0
A11: =E11&F11 -> VAV HW Valve 2W & 3-way NSR | B11: =IF(E11="","",VLOOKUP(A11,'Parts List'!A:E,5,FALSE)) -> N/A | D11: =$D$5*I11 -> 0 | E11: VAV HW Valve 2W & 3-way NSR | H11: 150 | I11: 0 | M11: =IF(H11="","",D11*H11) -> 0
A12: =E12&F12 -> Air Flow MonitorRetrofit Flow Ring for VAV Boxes | B12: =IF(E12="","",VLOOKUP(A12,'Parts List'!A:E,5,FALSE)) -> 36FMI | D12: =$D$5*I12 -> 0 | E12: Air Flow Monitor | F12: Retrofit Flow Ring for VAV Boxes | H12: =IF(E12="","",VLOOKUP(A12,'Parts List'!A:F,6,FALSE)) -> 95 | I12: 0 | M12: =IF(H12="","",D12*H12) -> 0
B13: =IF(E13="","",VLOOKUP(A13,'Parts List'!A:E,5,FALSE)) | H13: =IF(E13="","",VLOOKUP(A13,'Parts List'!A:F,6,FALSE)) | M13: =IF(H13="","",D13*H13)
A15: =E15&F15 -> Cooling Only VAV Boxes | D15: 0 | E15: Cooling Only VAV Boxes | I15: #/unit | N15: 1 | O15: Pts/VAV | P15: =D15*N15 -> 0 | Q15: points | R15: =P15*S15 -> 0 | S15: 550 | T15: per VAV | V15: =P15*W15 -> 0 | W15: 1 | X15: per VAV | Z15: =P15*AA15 -> 0 | AA15: 0.25 | AB15: per VAV | AD15: =P15*AE15 -> 0 | AE15: 0.25 | AF15: per VAV
A16: =E16&F16 -> ControllerOptimizer BACnet MSTP VAV Cntr w Act & VP, Bluetooth, 7 UIO, 5 SSR | B16: =IF(E16="","",VLOOKUP(A16,'Parts List'!A:E,5,FALSE)) -> VAA-VA75MB24NMC | D16: =$D$15*I16 -> 0 | E16: Controller | F16: Optimizer BACnet MSTP VAV Cntr w Act & VP, Bluetooth, 7 UIO, 5 SSR | H16: =IF(E16="","",VLOOKUP(A16,'Parts List'!A:F,6,FALSE)) -> 281.3558 | I16: 1 | J16: =D16 -> 0 | K16: =D16*70 -> 0 | M16: =IF(H16="","",D16*H16) -> 0
A17: =E17&F17 -> Temp SensorTR100 Space with LCD | B17: =IF(E17="","",VLOOKUP(A17,'Parts List'!A:E,5,FALSE)) -> TR100-T-G | D17: =$D$15*I17 -> 0 | E17: Temp Sensor | F17: TR100 Space with LCD | H17: =IF(E17="","",VLOOKUP(A17,'Parts List'!A:F,6,FALSE)) -> 128.71265 | I17: 1 | M17: =IF(H17="","",D17*H17) -> 0
A18: =E18&F18 -> Transformer40 VA | B18: =IF(E18="","",VLOOKUP(A18,'Parts List'!A:E,5,FALSE)) -> TR40VA001 | D18: =$D$15*I18 -> 0 | E18: Transformer | F18: 40 VA | H18: =IF(E18="","",VLOOKUP(A18,'Parts List'!A:F,6,FALSE)) -> 17.76 | I18: 0 | M18: =IF(H18="","",D18*H18) -> 0
A19: =E19&F19 -> Air Flow MonitorRetrofit Flow Ring for VAV Boxes | B19: =IF(E19="","",VLOOKUP(A19,'Parts List'!A:E,5,FALSE)) -> 36FMI | D19: =$D$15*I19 -> 0 | E19: Air Flow Monitor | F19: Retrofit Flow Ring for VAV Boxes | H19: =IF(E19="","",VLOOKUP(A19,'Parts List'!A:F,6,FALSE)) -> 95 | I19: 0 | M19: =IF(H19="","",D19*H19) -> 0
B20: =IF(E20="","",VLOOKUP(A20,'Parts List'!A:E,5,FALSE)) | H20: =IF(E20="","",VLOOKUP(A20,'Parts List'!A:F,6,FALSE)) | M20: =IF(H20="","",D20*H20)
D23: 0 | E23: Supply Air Boxes - CRC/Phoenix LV Wiring and Integration | I23: #/unit | N23: 1 | O23: Pts/VAV | P23: =D23*N23 -> 0 | Q23: points | R23: =P23*S23 -> 0 | S23: 750 | T23: per VAV | V23: =P23*W23 -> 0 | W23: 1 | X23: per VAV | Z23: =P23*AA23 -> 0 | AA23: 0.25 | AB23: per VAV | AD23: =P23*AE23 -> 0 | AE23: 0.25 | AF23: per VAV
A24: =E24&F24 | B24: =IF(E24="","",VLOOKUP(A24,'[2]Parts List'!A:E,5,FALSE)) | D24: =$D$23*I24 -> 0 | H24: =IF(E24="","",VLOOKUP(A24,'[2]Parts List'!A:F,6,FALSE)) | I24: 1 | J24: =D24 -> 0 | K24: =D24*50 -> 0 | M24: =IF(H24="","",D24*H24)
D27: 0 | E27: Exhaust Air Boxes - CRC/Phoenix LV Wiring and Integration | I27: #/unit | N27: 1 | O27: Pts/VAV | P27: =D27*N27 -> 0 | Q27: points | R27: =P27*S27 -> 0 | S27: 750 | T27: per VAV | V27: =P27*W27 -> 0 | W27: 1 | X27: per VAV | Z27: =P27*AA27 -> 0 | AA27: 0.25 | AB27: per VAV | AD27: =P27*AE27 -> 0 | AE27: 0.25 | AF27: per VAV
A28: =E28&F28 | B28: =IF(E28="","",VLOOKUP(A28,'[2]Parts List'!A:E,5,FALSE)) | D28: =$D$27*I28 -> 0 | H28: =IF(E28="","",VLOOKUP(A28,'[2]Parts List'!A:F,6,FALSE)) | I28: 1 | M28: =IF(H28="","",D28*H28)
D31: 0 | E31: Return Air Boxes - CRC/Phoenix LV Wiring and Integration | I31: #/unit | N31: 1 | O31: Pts/VAV | P31: =D31*N31 -> 0 | Q31: points | R31: =P31*S31 -> 0 | S31: 750 | T31: per VAV | V31: =P31*W31 -> 0 | W31: 1 | X31: per VAV | Z31: =P31*AA31 -> 0 | AA31: 0.25 | AB31: per VAV | AD31: =P31*AE31 -> 0 | AE31: 0.25 | AF31: per VAV
A32: =E32&F32 | B32: =IF(E32="","",VLOOKUP(A32,'[2]Parts List'!A:E,5,FALSE)) | D32: =$D$31*I32 -> 0 | H32: =IF(E32="","",VLOOKUP(A32,'[2]Parts List'!A:F,6,FALSE)) | I32: 1 | M32: =IF(H32="","",D32*H32)
D35: 0 | E35: OR Room Pressure Monitors - CRC/Phoenix LV Wiring and Integration | I35: #/unit | N35: 1 | O35: Pts/VAV | P35: =D35*N35 -> 0 | Q35: points | R35: =P35*S35 -> 0 | S35: 750 | T35: per VAV | V35: =P35*W35 -> 0 | W35: 1 | X35: per VAV | Z35: =P35*AA35 -> 0 | AA35: 0.25 | AB35: per VAV | AD35: =P35*AE35 -> 0 | AE35: 0.25 | AF35: per VAV
A36: =E36&F36 | B36: =IF(E36="","",VLOOKUP(A36,'[2]Parts List'!A:E,5,FALSE)) | D36: =$D$35*I36 -> 0 | H36: =IF(E36="","",VLOOKUP(A36,'[2]Parts List'!A:F,6,FALSE)) | I36: 1 | M36: =IF(H36="","",D36*H36)
A40: =E40&F40 -> Cooling Only VAV Box Transformers | D40: 0 | E40: Cooling Only VAV Box Transformers | I40: #/unit | N40: =SUM(I41:I43) -> 0 | O40: Pts/Unit | P40: =D40*N40 -> 0 | Q40: points | R40: =P40*S40 -> 0 | S40: 550 | T40: per Unit | V40: =P40*W40 -> 0 | W40: 0 | X40: per unit | Z40: =D40*AA40 -> 0 | AA40: 0 | AB40: per unit | AD40: =D40*AE40 -> 0 | AE40: 0 | AF40: per unit
A41: =E41&F41 -> Transformer(3) - 100 VA w Enclosure | B41: =IF(E41="","",VLOOKUP(A41,'Parts List'!A:E,5,FALSE)) -> PSH300A | D41: =$D$40*I41 -> 0 | E41: Transformer | F41: (3) - 100 VA w Enclosure | H41: =IF(E41="","",VLOOKUP(A41,'Parts List'!A:F,6,FALSE)) -> 314.8 | I41: 0 | M41: =IF(H41="","",D41*H41) -> 0
A42: =E42&F42 -> Transformer(5) - 100 VA w Enclosure | B42: =IF(E42="","",VLOOKUP(A42,'Parts List'!A:E,5,FALSE)) -> PSH500A | D42: =$D$40*I42 -> 0 | E42: Transformer | F42: (5) - 100 VA w Enclosure | H42: =IF(E42="","",VLOOKUP(A42,'Parts List'!A:F,6,FALSE)) -> 430.65 | I42: 0 | M42: =IF(H42="","",D42*H42) -> 0
A43: =E43&F43 | B43: =IF(E43="","",VLOOKUP(A43,'Parts List'!A:E,5,FALSE)) | D43: =$D$40*I43 -> 0 | H43: =IF(E43="","",VLOOKUP(A43,'Parts List'!A:F,6,FALSE)) | I43: 0 | M43: =IF(H43="","",D43*H43)
B44: =IF(E44="","",VLOOKUP(A44,'Parts List'!A:E,5,FALSE)) | H44: =IF(E44="","",VLOOKUP(A44,'Parts List'!A:F,6,FALSE)) | M44: =IF(H44="","",D44*H44)
A46: =E46&F46 -> VAV Air Handling Unit | D46: 0 | E46: VAV Air Handling Unit | I46: #/unit | N46: =SUM(I57:I73)+I52 -> 1 | O46: Pts/Unit | P46: =D46*N46 -> 0 | Q46: points | R46: =P46*S46 -> 0 | S46: 350 | T46: per point | V46: =P46*W46 -> 0 | W46: 1 | X46: per point | Z46: =D46*AA46 -> 0 | AA46: 4 | AB46: per unit | AD46: =D46*AE46 -> 0 | AE46: 6 | AF46: per unit
A47: =E47&F47 -> ControllerOptimizer Plant Cntr, 1 IP, 3 Ethernet Switched+4 RS485 Ports | B47: =IF(E47="","",VLOOKUP(A47,'Parts List'!A:E,5,FALSE)) -> N-ADV-134-H-C | D47: =$D$46*I47 -> 0 | E47: Controller | F47: Optimizer Plant Cntr, 1 IP, 3 Ethernet Switched+4 RS485 Ports | H47: =IF(E47="","",VLOOKUP(A47,'Parts List'!A:F,6,FALSE)) -> 875.1457 | I47: 0 | J47: =D47 -> 0 | K47: =D47*70 -> 0 | M47: =IF(H47="","",D47*H47) -> 0
A48: =E48&F48 -> Optimizer License with 18 Month SMA | B48: =IF(E48="","",VLOOKUP(A48,'Parts List'!A:E,5,FALSE)) -> Select Option | D48: =$D$46*I48 -> 0 | E48: Optimizer License with 18 Month SMA | H48: =IF(E48="","",VLOOKUP(A48,'Parts List'!A:F,6,FALSE)) -> 0 | I48: 0 | J48: =D48 -> 0 | K48: =D48*70 -> 0 | M48: =IF(H48="","",D48*H48) -> 0
A49: =E49&F49 -> I/O ModuleOptimzer Unitary Cntr 5-UI, 5-DI, 4-AO, 4-DO I/O Module | B49: =IF(E49="","",VLOOKUP(A49,'Parts List'!A:E,5,FALSE)) -> ISMA-B-MIX18 | D49: =$D$46*I49 -> 0 | E49: I/O Module | F49: Optimzer Unitary Cntr 5-UI, 5-DI, 4-AO, 4-DO I/O Module | H49: =IF(E49="","",VLOOKUP(A49,'Parts List'!A:F,6,FALSE)) -> 338.81 | I49: 0 | M49: =IF(H49="","",D49*H49) -> 0
A50: =E50&F50 -> Phoenix Controller Core License | B50: =IF(E50="","",VLOOKUP(A50,'Parts List'!A:E,5,FALSE)) -> Select Option | D50: =$D$46*I50 -> 0 | E50: Phoenix Controller Core License | H50: =IF(E50="","",VLOOKUP(A50,'Parts List'!A:F,6,FALSE)) -> 0 | I50: 0 | M50: =IF(H50="","",D50*H50) -> 0
A51: =E51&F51 -> Phoenix ILC SMA | B51: =IF(E51="","",VLOOKUP(A51,'Parts List'!A:E,5,FALSE)) -> Select Option | D51: =$D$46*I51 -> 0 | E51: Phoenix ILC SMA | H51: =IF(E51="","",VLOOKUP(A51,'Parts List'!A:F,6,FALSE)) -> 0 | I51: 0 | M51: =IF(H51="","",D51*H51) -> 0
A52: =E52&F52 -> Panel - Enclosure w SubpanelNema-1 Medium | B52: =IF(E52="","",VLOOKUP(A52,'Parts List'!A:E,5,FALSE)) -> RET1-262007BT-P | D52: =$D$46*I52 -> 0 | E52: Panel - Enclosure w Subpanel | F52: Nema-1 Medium | H52: =IF(E52="","",VLOOKUP(A52,'Parts List'!A:F,6,FALSE)) -> 436.83 | I52: 0 | M52: =IF(H52="","",D52*H52) -> 0
A53: =E53&F53 -> Relay24VAC DPDT with Base | B53: =IF(E53="","",VLOOKUP(A53,'Parts List'!A:E,5,FALSE)) -> RH2B-UAC24 + SH2B-05 | D53: =$D$46*I53 -> 0 | E53: Relay | F53: 24VAC DPDT with Base | H53: =IF(E53="","",VLOOKUP(A53,'Parts List'!A:F,6,FALSE)) -> 8.12 | I53: 0 | M53: =IF(H53="","",D53*H53) -> 0
A54: =E54&F54 -> Transformer75 VA with circuit breaker | B54: =IF(E54="","",VLOOKUP(A54,'Parts List'!A:E,5,FALSE)) -> TR75VA004 | D54: =$D$46*I54 -> 0 | E54: Transformer | F54: 75 VA with circuit breaker | H54: =IF(E54="","",VLOOKUP(A54,'Parts List'!A:F,6,FALSE)) -> 42.14 | I54: 0 | M54: =IF(H54="","",D54*H54) -> 0
...

Sheet Estimate 2
B1: =Totals!B1 -> ESTIMATING SHEET VERSION 8.6 | G1: Salesman: | H1: =Totals!H1 -> 0 | L1: 1 | N1: <- 1=Page Used, 0=Page not used
B2: Job Name: | C2: =Totals!C2 -> 0 | G2: Estimator: | H2: =Totals!H2 -> 0 | L2: =Totals!L2 -> 0
B3: Part Number | D3: QTY. | E3: MATERIAL DESCRIPTON | H3: LIST $ | J3: # of Contrs | K3: # of Points | M3: TOTAL | R3: Electrical Price Check | V3: Tech | Z3: Graphics | AD3: Programming
D5: 0 | E5: VAV Boxes w Heat | F5: Option | I5: #/unit | N5: 1 | O5: Pts/VAV | P5: =D5*N5 -> 0 | Q5: points | R5: =P5*S5 -> 0 | S5: 550 | T5: per VAV | V5: =P5*W5 -> 0 | W5: 1 | X5: per VAV | Z5: =P5*AA5 -> 0 | AA5: 0.25 | AB5: per VAV | AD5: =P5*AE5 -> 0 | AE5: 0.25 | AF5: per VAV
A6: =E6&F6 -> ControllerOptimizer BACnet MSTP VAV Cntr w Act & VP, Bluetooth, 7 UIO, 5 SSR | B6: =IF(E6="","",VLOOKUP(A6,'Parts List'!A:E,5,FALSE)) -> VAA-VA75MB24NMC | D6: =$D$5*I6 -> 0 | E6: Controller | F6: Optimizer BACnet MSTP VAV Cntr w Act & VP, Bluetooth, 7 UIO, 5 SSR | H6: =IF(E6="","",VLOOKUP(A6,'Parts List'!A:F,6,FALSE)) -> 281.3558 | I6: 1 | J6: =D6 -> 0 | K6: =D6*70 -> 0 | M6: =IF(H6="","",D6*H6) -> 0
A7: =E7&F7 -> Temp SensorTR100 Space with LCD | B7: =IF(E7="","",VLOOKUP(A7,'Parts List'!A:E,5,FALSE)) -> TR100-T-G | D7: =$D$5*I7 -> 0 | E7: Temp Sensor | F7: TR100 Space with LCD | H7: =IF(E7="","",VLOOKUP(A7,'Parts List'!A:F,6,FALSE)) -> 128.71265 | I7: 1 | M7: =IF(H7="","",D7*H7) -> 0
A8: =E8&F8 -> Temp SensorDuct Insertion Sensor | B8: =IF(E8="","",VLOOKUP(A8,'Parts List'!A:E,5,FALSE)) -> C7041B2005 | D8: =$D$5*I8 -> 0 | E8: Temp Sensor | F8: Duct Insertion Sensor | H8: =IF(E8="","",VLOOKUP(A8,'Parts List'!A:F,6,FALSE)) -> 23.18855 | I8: 1 | M8: =IF(H8="","",D8*H8) -> 0
A9: =E9&F9 -> Current SwDigital Status Switch | B9: =IF(E9="","",VLOOKUP(A9,'Parts List'!A:E,5,FALSE)) -> H600 | D9: =$D$5*I9 -> 0 | E9: Current Sw | F9: Digital Status Switch | H9: =IF(E9="","",VLOOKUP(A9,'Parts List'!A:F,6,FALSE)) -> 31.43 | I9: 0 | M9: =IF(H9="","",D9*H9) -> 0
A10: =E10&F10 -> RelayRIB Pilot Relay | B10: =IF(E10="","",VLOOKUP(A10,'Parts List'!A:E,5,FALSE)) -> RIBU1C | D10: =$D$5*I10 -> 0 | E10: Relay | F10: RIB Pilot Relay | H10: =IF(E10="","",VLOOKUP(A10,'Parts List'!A:F,6,FALSE)) -> 14.36 | I10: 0 | M10: =IF(H10="","",D10*H10) -> 0
A11: =E11&F11 -> VAV HW Valve 2W & 3-way NSR | B11: =IF(E11="","",VLOOKUP(A11,'Parts List'!A:E,5,FALSE)) -> N/A | D11: =$D$5*I11 -> 0 | E11: VAV HW Valve 2W & 3-way NSR | H11: 150 | I11: 0 | M11: =IF(H11="","",D11*H11) -> 0
A12: =E12&F12 -> Air Flow MonitorRetrofit Flow Ring for VAV Boxes | B12: =IF(E12="","",VLOOKUP(A12,'Parts List'!A:E,5,FALSE)) -> 36FMI | D12: =$D$5*I12 -> 0 | E12: Air Flow Monitor | F12: Retrofit Flow Ring for VAV Boxes | H12: =IF(E12="","",VLOOKUP(A12,'Parts List'!A:F,6,FALSE)) -> 95 | I12: 0 | M12: =IF(H12="","",D12*H12) -> 0
B13: =IF(E13="","",VLOOKUP(A13,'Parts List'!A:E,5,FALSE)) | H13: =IF(E13="","",VLOOKUP(A13,'Parts List'!A:F,6,FALSE)) | M13: =IF(H13="","",D13*H13)
A15: =E15&F15 -> Cooling Only VAV Boxes | D15: 0 | E15: Cooling Only VAV Boxes | I15: #/unit | N15: 1 | O15: Pts/VAV | P15: =D15*N15 -> 0 | Q15: points | R15: =P15*S15 -> 0 | S15: 550 | T15: per VAV | V15: =P15*W15 -> 0 | W15: 1 | X15: per VAV | Z15: =P15*AA15 -> 0 | AA15: 0.25 | AB15: per VAV | AD15: =P15*AE15 -> 0 | AE15: 0.25 | AF15: per VAV
A16: =E16&F16 -> ControllerOptimizer BACnet MSTP VAV Cntr w Act & VP, Bluetooth, 7 UIO, 5 SSR | B16: =IF(E16="","",VLOOKUP(A16,'Parts List'!A:E,5,FALSE)) -> VAA-VA75MB24NMC | D16: =$D$15*I16 -> 0 | E16: Controller | F16: Optimizer BACnet MSTP VAV Cntr w Act & VP, Bluetooth, 7 UIO, 5 SSR | H16: =IF(E16="","",VLOOKUP(A16,'Parts List'!A:F,6,FALSE)) -> 281.3558 | I16: 1 | J16: =D16 -> 0 | K16: =D16*70 -> 0 | M16: =IF(H16="","",D16*H16) -> 0
A17: =E17&F17 -> Temp SensorTR100 Space with LCD | B17: =IF(E17="","",VLOOKUP(A17,'Parts List'!A:E,5,FALSE)) -> TR100-T-G | D17: =$D$15*I17 -> 0 | E17: Temp Sensor | F17: TR100 Space with LCD | H17: =IF(E17="","",VLOOKUP(A17,'Parts List'!A:F,6,FALSE)) -> 128.71265 | I17: 1 | M17: =IF(H17="","",D17*H17) -> 0
A18: =E18&F18 -> Transformer40 VA | B18: =IF(E18="","",VLOOKUP(A18,'Parts List'!A:E,5,FALSE)) -> TR40VA001 | D18: =$D$15*I18 -> 0 | E18: Transformer | F18: 40 VA | H18: =IF(E18="","",VLOOKUP(A18,'Parts List'!A:F,6,FALSE)) -> 17.76 | I18: 0 | M18: =IF(H18="","",D18*H18) -> 0
A19: =E19&F19 -> Air Flow MonitorRetrofit Flow Ring for VAV Boxes | B19: =IF(E19="","",VLOOKUP(A19,'Parts List'!A:E,5,FALSE)) -> 36FMI | D19: =$D$15*I19 -> 0 | E19: Air Flow Monitor | F19: Retrofit Flow Ring for VAV Boxes | H19: =IF(E19="","",VLOOKUP(A19,'Parts List'!A:F,6,FALSE)) -> 95 | I19: 0 | M19: =IF(H19="","",D19*H19) -> 0
B20: =IF(E20="","",VLOOKUP(A20,'Parts List'!A:E,5,FALSE)) | H20: =IF(E20="","",VLOOKUP(A20,'Parts List'!A:F,6,FALSE)) | M20: =IF(H20="","",D20*H20)
D23: 0 | E23: Supply Air Boxes - CRC/Phoenix LV Wiring and Integration | I23: #/unit | N23: 1 | O23: Pts/VAV | P23: =D23*N23 -> 0 | Q23: points | R23: =P23*S23 -> 0 | S23: 750 | T23: per VAV | V23: =P23*W23 -> 0 | W23: 1 | X23: per VAV | Z23: =P23*AA23 -> 0 | AA23: 0.25 | AB23: per VAV | AD23: =P23*AE23 -> 0 | AE23: 0.25 | AF23: per VAV
A24: =E24&F24 | B24: =IF(E24="","",VLOOKUP(A24,'[2]Parts List'!A:E,5,FALSE)) | D24: =$D$23*I24 -> 0 | H24: =IF(E24="","",VLOOKUP(A24,'[2]Parts List'!A:F,6,FALSE)) | I24: 1 | J24: =D24 -> 0 | K24: =D24*50 -> 0 | M24: =IF(H24="","",D24*H24)
D27: 0 | E27: Exhaust Air Boxes - CRC/Phoenix LV Wiring and Integration | I27: #/unit | N27: 1 | O27: Pts/VAV | P27: =D27*N27 -> 0 | Q27: points | R27: =P27*S27 -> 0 | S27: 750 | T27: per VAV | V27: =P27*W27 -> 0 | W27: 1 | X27: per VAV | Z27: =P27*AA27 -> 0 | AA27: 0.25 | AB27: per VAV | AD27: =P27*AE27 -> 0 | AE27: 0.25 | AF27: per VAV
A28: =E28&F28 | B28: =IF(E28="","",VLOOKUP(A28,'[2]Parts List'!A:E,5,FALSE)) | D28: =$D$27*I28 -> 0 | H28: =IF(E28="","",VLOOKUP(A28,'[2]Parts List'!A:F,6,FALSE)) | I28: 1 | M28: =IF(H28="","",D28*H28)
D31: 0 | E31: Return Air Boxes - CRC/Phoenix LV Wiring and Integration | I31: #/unit | N31: 1 | O31: Pts/VAV | P31: =D31*N31 -> 0 | Q31: points | R31: =P31*S31 -> 0 | S31: 750 | T31: per VAV | V31: =P31*W31 -> 0 | W31: 1 | X31: per VAV | Z31: =P31*AA31 -> 0 | AA31: 0.25 | AB31: per VAV | AD31: =P31*AE31 -> 0 | AE31: 0.25 | AF31: per VAV
A32: =E32&F32 | B32: =IF(E32="","",VLOOKUP(A32,'[2]Parts List'!A:E,5,FALSE)) | D32: =$D$31*I32 -> 0 | H32: =IF(E32="","",VLOOKUP(A32,'[2]Parts List'!A:F,6,FALSE)) | I32: 1 | M32: =IF(H32="","",D32*H32)
D35: 0 | E35: OR Room Pressure Monitors - CRC/Phoenix LV Wiring and Integration | I35: #/unit | N35: 1 | O35: Pts/VAV | P35: =D35*N35 -> 0 | Q35: points | R35: =P35*S35 -> 0 | S35: 750 | T35: per VAV | V35: =P35*W35 -> 0 | W35: 1 | X35: per VAV | Z35: =P35*AA35 -> 0 | AA35: 0.25 | AB35: per VAV | AD35: =P35*AE35 -> 0 | AE35: 0.25 | AF35: per VAV
A36: =E36&F36 | B36: =IF(E36="","",VLOOKUP(A36,'[2]Parts List'!A:E,5,FALSE)) | D36: =$D$35*I36 -> 0 | H36: =IF(E36="","",VLOOKUP(A36,'[2]Parts List'!A:F,6,FALSE)) | I36: 1 | M36: =IF(H36="","",D36*H36)
A40: =E40&F40 -> Cooling Only VAV Box Transformers | D40: 0 | E40: Cooling Only VAV Box Transformers | I40: #/unit | N40: =SUM(I41:I43) -> 0 | O40: Pts/Unit | P40: =D40*N40 -> 0 | Q40: points | R40: =P40*S40 -> 0 | S40: 550 | T40: per Unit | V40: =P40*W40 -> 0 | W40: 0 | X40: per unit | Z40: =D40*AA40 -> 0 | AA40: 0 | AB40: per unit | AD40: =D40*AE40 -> 0 | AE40: 0 | AF40: per unit
A41: =E41&F41 -> Transformer(3) - 100 VA w Enclosure | B41: =IF(E41="","",VLOOKUP(A41,'Parts List'!A:E,5,FALSE)) -> PSH300A | D41: =$D$40*I41 -> 0 | E41: Transformer | F41: (3) - 100 VA w Enclosure | H41: =IF(E41="","",VLOOKUP(A41,'Parts List'!A:F,6,FALSE)) -> 314.8 | I41: 0 | M41: =IF(H41="","",D41*H41) -> 0
A42: =E42&F42 -> Transformer(5) - 100 VA w Enclosure | B42: =IF(E42="","",VLOOKUP(A42,'Parts List'!A:E,5,FALSE)) -> PSH500A | D42: =$D$40*I42 -> 0 | E42: Transformer | F42: (5) - 100 VA w Enclosure | H42: =IF(E42="","",VLOOKUP(A42,'Parts List'!A:F,6,FALSE)) -> 430.65 | I42: 0 | M42: =IF(H42="","",D42*H42) -> 0
A43: =E43&F43 | B43: =IF(E43="","",VLOOKUP(A43,'Parts List'!A:E,5,FALSE)) | D43: =$D$40*I43 -> 0 | H43: =IF(E43="","",VLOOKUP(A43,'Parts List'!A:F,6,FALSE)) | I43: 0 | M43: =IF(H43="","",D43*H43)
B44: =IF(E44="","",VLOOKUP(A44,'Parts List'!A:E,5,FALSE)) | H44: =IF(E44="","",VLOOKUP(A44,'Parts List'!A:F,6,FALSE)) | M44: =IF(H44="","",D44*H44)
A46: =E46&F46 -> VAV Air Handling Unit | D46: 0 | E46: VAV Air Handling Unit | I46: #/unit | N46: =SUM(I57:I73)+I52 -> 1 | O46: Pts/Unit | P46: =D46*N46 -> 0 | Q46: points | R46: =P46*S46 -> 0 | S46: 350 | T46: per point | V46: =P46*W46 -> 0 | W46: 1 | X46: per point | Z46: =D46*AA46 -> 0 | AA46: 4 | AB46: per unit | AD46: =D46*AE46 -> 0 | AE46: 6 | AF46: per unit
A47: =E47&F47 -> ControllerOptimizer Plant Cntr, 1 IP, 3 Ethernet Switched+4 RS485 Ports | B47: =IF(E47="","",VLOOKUP(A47,'Parts List'!A:E,5,FALSE)) -> N-ADV-134-H-C | D47: =$D$46*I47 -> 0 | E47: Controller | F47: Optimizer Plant Cntr, 1 IP, 3 Ethernet Switched+4 RS485 Ports | H47: =IF(E47="","",VLOOKUP(A47,'Parts List'!A:F,6,FALSE)) -> 875.1457 | I47: 0 | J47: =D47 -> 0 | K47: =D47*70 -> 0 | M47: =IF(H47="","",D47*H47) -> 0
A48: =E48&F48 -> Optimizer License with 18 Month SMA | B48: =IF(E48="","",VLOOKUP(A48,'Parts List'!A:E,5,FALSE)) -> Select Option | D48: =$D$46*I48 -> 0 | E48: Optimizer License with 18 Month SMA | H48: =IF(E48="","",VLOOKUP(A48,'Parts List'!A:F,6,FALSE)) -> 0 | I48: 0 | J48: =D48 -> 0 | K48: =D48*70 -> 0 | M48: =IF(H48="","",D48*H48) -> 0
A49: =E49&F49 -> I/O ModuleOptimzer Unitary Cntr 5-UI, 5-DI, 4-AO, 4-DO I/O Module | B49: =IF(E49="","",VLOOKUP(A49,'Parts List'!A:E,5,FALSE)) -> ISMA-B-MIX18 | D49: =$D$46*I49 -> 0 | E49: I/O Module | F49: Optimzer Unitary Cntr 5-UI, 5-DI, 4-AO, 4-DO I/O Module | H49: =IF(E49="","",VLOOKUP(A49,'Parts List'!A:F,6,FALSE)) -> 338.81 | I49: 0 | M49: =IF(H49="","",D49*H49) -> 0
A50: =E50&F50 -> Phoenix Controller Core License | B50: =IF(E50="","",VLOOKUP(A50,'Parts List'!A:E,5,FALSE)) -> Select Option | D50: =$D$46*I50 -> 0 | E50: Phoenix Controller Core License | H50: =IF(E50="","",VLOOKUP(A50,'Parts List'!A:F,6,FALSE)) -> 0 | I50: 0 | M50: =IF(H50="","",D50*H50) -> 0
A51: =E51&F51 -> Phoenix ILC SMA | B51: =IF(E51="","",VLOOKUP(A51,'Parts List'!A:E,5,FALSE)) -> Select Option | D51: =$D$46*I51 -> 0 | E51: Phoenix ILC SMA | H51: =IF(E51="","",VLOOKUP(A51,'Parts List'!A:F,6,FALSE)) -> 0 | I51: 0 | M51: =IF(H51="","",D51*H51) -> 0
A52: =E52&F52 -> Panel - Enclosure w SubpanelNema-1 Medium | B52: =IF(E52="","",VLOOKUP(A52,'Parts List'!A:E,5,FALSE)) -> RET1-262007BT-P | D52: =$D$46*I52 -> 0 | E52: Panel - Enclosure w Subpanel | F52: Nema-1 Medium | H52: =IF(E52="","",VLOOKUP(A52,'Parts List'!A:F,6,FALSE)) -> 436.83 | I52: 0 | M52: =IF(H52="","",D52*H52) -> 0
A53: =E53&F53 -> Relay24VAC DPDT with Base | B53: =IF(E53="","",VLOOKUP(A53,'Parts List'!A:E,5,FALSE)) -> RH2B-UAC24 + SH2B-05 | D53: =$D$46*I53 -> 0 | E53: Relay | F53: 24VAC DPDT with Base | H53: =IF(E53="","",VLOOKUP(A53,'Parts List'!A:F,6,FALSE)) -> 8.12 | I53: 0 | M53: =IF(H53="","",D53*H53) -> 0
A54: =E54&F54 -> Transformer75 VA with circuit breaker | B54: =IF(E54="","",VLOOKUP(A54,'Parts List'!A:E,5,FALSE)) -> TR75VA004 | D54: =$D$46*I54 -> 0 | E54: Transformer | F54: 75 VA with circuit breaker | H54: =IF(E54="","",VLOOKUP(A54,'Parts List'!A:F,6,FALSE)) -> 42.14 | I54: 0 | M54: =IF(H54="","",D54*H54) -> 0
...

Sheet Estimate 3
B1: =Totals!B1 -> ESTIMATING SHEET VERSION 8.6 | G1: Salesman: | H1: =Totals!H1 -> 0 | L1: 1 | N1: <- 1=Page Used, 0=Page not used
B2: Job Name: | C2: =Totals!C2 -> 0 | G2: Estimator: | H2: =Totals!H2 -> 0 | L2: =Totals!L2 -> 0
B3: Part Number | D3: QTY. | E3: MATERIAL DESCRIPTON | H3: LIST $ | J3: # of Contrs | K3: # of Points | M3: TOTAL | R3: Electrical Price Check | V3: Tech | Z3: Graphics | AD3: Programming
D5: 0 | E5: VAV Boxes w Heat | F5: Option | I5: #/unit | N5: 1 | O5: Pts/VAV | P5: =D5*N5 -> 0 | Q5: points | R5: =P5*S5 -> 0 | S5: 550 | T5: per VAV | V5: =P5*W5 -> 0 | W5: 1 | X5: per VAV | Z5: =P5*AA5 -> 0 | AA5: 0.25 | AB5: per VAV | AD5: =P5*AE5 -> 0 | AE5: 0.25 | AF5: per VAV
A6: =E6&F6 -> ControllerOptimizer BACnet MSTP VAV Cntr w Act & VP, Bluetooth, 7 UIO, 5 SSR | B6: =IF(E6="","",VLOOKUP(A6,'Parts List'!A:E,5,FALSE)) -> VAA-VA75MB24NMC | D6: =$D$5*I6 -> 0 | E6: Controller | F6: Optimizer BACnet MSTP VAV Cntr w Act & VP, Bluetooth, 7 UIO, 5 SSR | H6: =IF(E6="","",VLOOKUP(A6,'Parts List'!A:F,6,FALSE)) -> 281.3558 | I6: 1 | J6: =D6 -> 0 | K6: =D6*70 -> 0 | M6: =IF(H6="","",D6*H6) -> 0
A7: =E7&F7 -> Temp SensorTR100 Space with LCD | B7: =IF(E7="","",VLOOKUP(A7,'Parts List'!A:E,5,FALSE)) -> TR100-T-G | D7: =$D$5*I7 -> 0 | E7: Temp Sensor | F7: TR100 Space with LCD | H7: =IF(E7="","",VLOOKUP(A7,'Parts List'!A:F,6,FALSE)) -> 128.71265 | I7: 1 | M7: =IF(H7="","",D7*H7) -> 0
A8: =E8&F8 -> Temp SensorDuct Insertion Sensor | B8: =IF(E8="","",VLOOKUP(A8,'Parts List'!A:E,5,FALSE)) -> C7041B2005 | D8: =$D$5*I8 -> 0 | E8: Temp Sensor | F8: Duct Insertion Sensor | H8: =IF(E8="","",VLOOKUP(A8,'Parts List'!A:F,6,FALSE)) -> 23.18855 | I8: 1 | M8: =IF(H8="","",D8*H8) -> 0
A9: =E9&F9 -> Current SwDigital Status Switch | B9: =IF(E9="","",VLOOKUP(A9,'Parts List'!A:E,5,FALSE)) -> H600 | D9: =$D$5*I9 -> 0 | E9: Current Sw | F9: Digital Status Switch | H9: =IF(E9="","",VLOOKUP(A9,'Parts List'!A:F,6,FALSE)) -> 31.43 | I9: 0 | M9: =IF(H9="","",D9*H9) -> 0
A10: =E10&F10 -> RelayRIB Pilot Relay | B10: =IF(E10="","",VLOOKUP(A10,'Parts List'!A:E,5,FALSE)) -> RIBU1C | D10: =$D$5*I10 -> 0 | E10: Relay | F10: RIB Pilot Relay | H10: =IF(E10="","",VLOOKUP(A10,'Parts List'!A:F,6,FALSE)) -> 14.36 | I10: 0 | M10: =IF(H10="","",D10*H10) -> 0
A11: =E11&F11 -> VAV HW Valve 2W & 3-way NSR | B11: =IF(E11="","",VLOOKUP(A11,'Parts List'!A:E,5,FALSE)) -> N/A | D11: =$D$5*I11 -> 0 | E11: VAV HW Valve 2W & 3-way NSR | H11: 150 | I11: 0 | M11: =IF(H11="","",D11*H11) -> 0
A12: =E12&F12 -> Air Flow MonitorRetrofit Flow Ring for VAV Boxes | B12: =IF(E12="","",VLOOKUP(A12,'Parts List'!A:E,5,FALSE)) -> 36FMI | D12: =$D$5*I12 -> 0 | E12: Air Flow Monitor | F12: Retrofit Flow Ring for VAV Boxes | H12: =IF(E12="","",VLOOKUP(A12,'Parts List'!A:F,6,FALSE)) -> 95 | I12: 0 | M12: =IF(H12="","",D12*H12) -> 0
B13: =IF(E13="","",VLOOKUP(A13,'Parts List'!A:E,5,FALSE)) | H13: =IF(E13="","",VLOOKUP(A13,'Parts List'!A:F,6,FALSE)) | M13: =IF(H13="","",D13*H13)
A15: =E15&F15 -> Cooling Only VAV Boxes | D15: 0 | E15: Cooling Only VAV Boxes | I15: #/unit | N15: 1 | O15: Pts/VAV | P15: =D15*N15 -> 0 | Q15: points | R15: =P15*S15 -> 0 | S15: 550 | T15: per VAV | V15: =P15*W15 -> 0 | W15: 1 | X15: per VAV | Z15: =P15*AA15 -> 0 | AA15: 0.25 | AB15: per VAV | AD15: =P15*AE15 -> 0 | AE15: 0.25 | AF15: per VAV
A16: =E16&F16 -> ControllerOptimizer BACnet MSTP VAV Cntr w Act & VP, Bluetooth, 7 UIO, 5 SSR | B16: =IF(E16="","",VLOOKUP(A16,'Parts List'!A:E,5,FALSE)) -> VAA-VA75MB24NMC | D16: =$D$15*I16 -> 0 | E16: Controller | F16: Optimizer BACnet MSTP VAV Cntr w Act & VP, Bluetooth, 7 UIO, 5 SSR | H16: =IF(E16="","",VLOOKUP(A16,'Parts List'!A:F,6,FALSE)) -> 281.3558 | I16: 1 | J16: =D16 -> 0 | K16: =D16*70 -> 0 | M16: =IF(H16="","",D16*H16) -> 0
A17: =E17&F17 -> Temp SensorTR100 Space with LCD | B17: =IF(E17="","",VLOOKUP(A17,'Parts List'!A:E,5,FALSE)) -> TR100-T-G | D17: =$D$15*I17 -> 0 | E17: Temp Sensor | F17: TR100 Space with LCD | H17: =IF(E17="","",VLOOKUP(A17,'Parts List'!A:F,6,FALSE)) -> 128.71265 | I17: 1 | M17: =IF(H17="","",D17*H17) -> 0
A18: =E18&F18 -> Transformer40 VA | B18: =IF(E18="","",VLOOKUP(A18,'Parts List'!A:E,5,FALSE)) -> TR40VA001 | D18: =$D$15*I18 -> 0 | E18: Transformer | F18: 40 VA | H18: =IF(E18="","",VLOOKUP(A18,'Parts List'!A:F,6,FALSE)) -> 17.76 | I18: 0 | M18: =IF(H18="","",D18*H18) -> 0
A19: =E19&F19 -> Air Flow MonitorRetrofit Flow Ring for VAV Boxes | B19: =IF(E19="","",VLOOKUP(A19,'Parts List'!A:E,5,FALSE)) -> 36FMI | D19: =$D$15*I19 -> 0 | E19: Air Flow Monitor | F19: Retrofit Flow Ring for VAV Boxes | H19: =IF(E19="","",VLOOKUP(A19,'Parts List'!A:F,6,FALSE)) -> 95 | I19: 0 | M19: =IF(H19="","",D19*H19) -> 0
B20: =IF(E20="","",VLOOKUP(A20,'Parts List'!A:E,5,FALSE)) | H20: =IF(E20="","",VLOOKUP(A20,'Parts List'!A:F,6,FALSE)) | M20: =IF(H20="","",D20*H20)
D23: 0 | E23: Supply Air Boxes - CRC/Phoenix LV Wiring and Integration | I23: #/unit | N23: 1 | O23: Pts/VAV | P23: =D23*N23 -> 0 | Q23: points | R23: =P23*S23 -> 0 | S23: 750 | T23: per VAV | V23: =P23*W23 -> 0 | W23: 1 | X23: per VAV | Z23: =P23*AA23 -> 0 | AA23: 0.25 | AB23: per VAV | AD23: =P23*AE23 -> 0 | AE23: 0.25 | AF23: per VAV
A24: =E24&F24 | B24: =IF(E24="","",VLOOKUP(A24,'[2]Parts List'!A:E,5,FALSE)) | D24: =$D$23*I24 -> 0 | H24: =IF(E24="","",VLOOKUP(A24,'[2]Parts List'!A:F,6,FALSE)) | I24: 1 | J24: =D24 -> 0 | K24: =D24*50 -> 0 | M24: =IF(H24="","",D24*H24)
D27: 0 | E27: Exhaust Air Boxes - CRC/Phoenix LV Wiring and Integration | I27: #/unit | N27: 1 | O27: Pts/VAV | P27: =D27*N27 -> 0 | Q27: points | R27: =P27*S27 -> 0 | S27: 750 | T27: per VAV | V27: =P27*W27 -> 0 | W27: 1 | X27: per VAV | Z27: =P27*AA27 -> 0 | AA27: 0.25 | AB27: per VAV | AD27: =P27*AE27 -> 0 | AE27: 0.25 | AF27: per VAV
A28: =E28&F28 | B28: =IF(E28="","",VLOOKUP(A28,'[2]Parts List'!A:E,5,FALSE)) | D28: =$D$27*I28 -> 0 | H28: =IF(E28="","",VLOOKUP(A28,'[2]Parts List'!A:F,6,FALSE)) | I28: 1 | M28: =IF(H28="","",D28*H28)
D31: 0 | E31: Return Air Boxes - CRC/Phoenix LV Wiring and Integration | I31: #/unit | N31: 1 | O31: Pts/VAV | P31: =D31*N31 -> 0 | Q31: points | R31: =P31*S31 -> 0 | S31: 750 | T31: per VAV | V31: =P31*W31 -> 0 | W31: 1 | X31: per VAV | Z31: =P31*AA31 -> 0 | AA31: 0.25 | AB31: per VAV | AD31: =P31*AE31 -> 0 | AE31: 0.25 | AF31: per VAV
A32: =E32&F32 | B32: =IF(E32="","",VLOOKUP(A32,'[2]Parts List'!A:E,5,FALSE)) | D32: =$D$31*I32 -> 0 | H32: =IF(E32="","",VLOOKUP(A32,'[2]Parts List'!A:F,6,FALSE)) | I32: 1 | M32: =IF(H32="","",D32*H32)
D35: 0 | E35: OR Room Pressure Monitors - CRC/Phoenix LV Wiring and Integration | I35: #/unit | N35: 1 | O35: Pts/VAV | P35: =D35*N35 -> 0 | Q35: points | R35: =P35*S35 -> 0 | S35: 750 | T35: per VAV | V35: =P35*W35 -> 0 | W35: 1 | X35: per VAV | Z35: =P35*AA35 -> 0 | AA35: 0.25 | AB35: per VAV | AD35: =P35*AE35 -> 0 | AE35: 0.25 | AF35: per VAV
A36: =E36&F36 | B36: =IF(E36="","",VLOOKUP(A36,'[2]Parts List'!A:E,5,FALSE)) | D36: =$D$35*I36 -> 0 | H36: =IF(E36="","",VLOOKUP(A36,'[2]Parts List'!A:F,6,FALSE)) | I36: 1 | M36: =IF(H36="","",D36*H36)
A40: =E40&F40 -> Cooling Only VAV Box Transformers | D40: 0 | E40: Cooling Only VAV Box Transformers | I40: #/unit | N40: =SUM(I41:I43) -> 0 | O40: Pts/Unit | P40: =D40*N40 -> 0 | Q40: points | R40: =P40*S40 -> 0 | S40: 550 | T40: per Unit | V40: =P40*W40 -> 0 | W40: 0 | X40: per unit | Z40: =D40*AA40 -> 0 | AA40: 0 | AB40: per unit | AD40: =D40*AE40 -> 0 | AE40: 0 | AF40: per unit
A41: =E41&F41 -> Transformer(3) - 100 VA w Enclosure | B41: =IF(E41="","",VLOOKUP(A41,'Parts List'!A:E,5,FALSE)) -> PSH300A | D41: =$D$40*I41 -> 0 | E41: Transformer | F41: (3) - 100 VA w Enclosure | H41: =IF(E41="","",VLOOKUP(A41,'Parts List'!A:F,6,FALSE)) -> 314.8 | I41: 0 | M41: =IF(H41="","",D41*H41) -> 0
A42: =E42&F42 -> Transformer(5) - 100 VA w Enclosure | B42: =IF(E42="","",VLOOKUP(A42,'Parts List'!A:E,5,FALSE)) -> PSH500A | D42: =$D$40*I42 -> 0 | E42: Transformer | F42: (5) - 100 VA w Enclosure | H42: =IF(E42="","",VLOOKUP(A42,'Parts List'!A:F,6,FALSE)) -> 430.65 | I42: 0 | M42: =IF(H42="","",D42*H42) -> 0
A43: =E43&F43 | B43: =IF(E43="","",VLOOKUP(A43,'Parts List'!A:E,5,FALSE)) | D43: =$D$40*I43 -> 0 | H43: =IF(E43="","",VLOOKUP(A43,'Parts List'!A:F,6,FALSE)) | I43: 0 | M43: =IF(H43="","",D43*H43)
B44: =IF(E44="","",VLOOKUP(A44,'Parts List'!A:E,5,FALSE)) | H44: =IF(E44="","",VLOOKUP(A44,'Parts List'!A:F,6,FALSE)) | M44: =IF(H44="","",D44*H44)
A46: =E46&F46 -> VAV Air Handling Unit | D46: 0 | E46: VAV Air Handling Unit | I46: #/unit | N46: =SUM(I57:I73)+I52 -> 1 | O46: Pts/Unit | P46: =D46*N46 -> 0 | Q46: points | R46: =P46*S46 -> 0 | S46: 350 | T46: per point | V46: =P46*W46 -> 0 | W46: 1 | X46: per point | Z46: =D46*AA46 -> 0 | AA46: 4 | AB46: per unit | AD46: =D46*AE46 -> 0 | AE46: 6 | AF46: per unit
A47: =E47&F47 -> ControllerOptimizer Plant Cntr, 1 IP, 3 Ethernet Switched+4 RS485 Ports | B47: =IF(E47="","",VLOOKUP(A47,'Parts List'!A:E,5,FALSE)) -> N-ADV-134-H-C | D47: =$D$46*I47 -> 0 | E47: Controller | F47: Optimizer Plant Cntr, 1 IP, 3 Ethernet Switched+4 RS485 Ports | H47: =IF(E47="","",VLOOKUP(A47,'Parts List'!A:F,6,FALSE)) -> 875.1457 | I47: 0 | J47: =D47 -> 0 | K47: =D47*70 -> 0 | M47: =IF(H47="","",D47*H47) -> 0
A48: =E48&F48 -> Optimizer License with 18 Month SMA | B48: =IF(E48="","",VLOOKUP(A48,'Parts List'!A:E,5,FALSE)) -> Select Option | D48: =$D$46*I48 -> 0 | E48: Optimizer License with 18 Month SMA | H48: =IF(E48="","",VLOOKUP(A48,'Parts List'!A:F,6,FALSE)) -> 0 | I48: 0 | J48: =D48 -> 0 | K48: =D48*70 -> 0 | M48: =IF(H48="","",D48*H48) -> 0
A49: =E49&F49 -> I/O ModuleOptimzer Unitary Cntr 5-UI, 5-DI, 4-AO, 4-DO I/O Module | B49: =IF(E49="","",VLOOKUP(A49,'Parts List'!A:E,5,FALSE)) -> ISMA-B-MIX18 | D49: =$D$46*I49 -> 0 | E49: I/O Module | F49: Optimzer Unitary Cntr 5-UI, 5-DI, 4-AO, 4-DO I/O Module | H49: =IF(E49="","",VLOOKUP(A49,'Parts List'!A:F,6,FALSE)) -> 338.81 | I49: 0 | M49: =IF(H49="","",D49*H49) -> 0
A50: =E50&F50 -> Phoenix Controller Core License | B50: =IF(E50="","",VLOOKUP(A50,'Parts List'!A:E,5,FALSE)) -> Select Option | D50: =$D$46*I50 -> 0 | E50: Phoenix Controller Core License | H50: =IF(E50="","",VLOOKUP(A50,'Parts List'!A:F,6,FALSE)) -> 0 | I50: 0 | M50: =IF(H50="","",D50*H50) -> 0
A51: =E51&F51 -> Phoenix ILC SMA | B51: =IF(E51="","",VLOOKUP(A51,'Parts List'!A:E,5,FALSE)) -> Select Option | D51: =$D$46*I51 -> 0 | E51: Phoenix ILC SMA | H51: =IF(E51="","",VLOOKUP(A51,'Parts List'!A:F,6,FALSE)) -> 0 | I51: 0 | M51: =IF(H51="","",D51*H51) -> 0
A52: =E52&F52 -> Panel - Enclosure w SubpanelNema-1 Medium | B52: =IF(E52="","",VLOOKUP(A52,'Parts List'!A:E,5,FALSE)) -> RET1-262007BT-P | D52: =$D$46*I52 -> 0 | E52: Panel - Enclosure w Subpanel | F52: Nema-1 Medium | H52: =IF(E52="","",VLOOKUP(A52,'Parts List'!A:F,6,FALSE)) -> 436.83 | I52: 0 | M52: =IF(H52="","",D52*H52) -> 0
A53: =E53&F53 -> Relay24VAC DPDT with Base | B53: =IF(E53="","",VLOOKUP(A53,'Parts List'!A:E,5,FALSE)) -> RH2B-UAC24 + SH2B-05 | D53: =$D$46*I53 -> 0 | E53: Relay | F53: 24VAC DPDT with Base | H53: =IF(E53="","",VLOOKUP(A53,'Parts List'!A:F,6,FALSE)) -> 8.12 | I53: 0 | M53: =IF(H53="","",D53*H53) -> 0
A54: =E54&F54 -> Transformer75 VA with circuit breaker | B54: =IF(E54="","",VLOOKUP(A54,'Parts List'!A:E,5,FALSE)) -> TR75VA004 | D54: =$D$46*I54 -> 0 | E54: Transformer | F54: 75 VA with circuit breaker | H54: =IF(E54="","",VLOOKUP(A54,'Parts List'!A:F,6,FALSE)) -> 42.14 | I54: 0 | M54: =IF(H54="","",D54*H54) -> 0
...

Sheet Estimate 4
B1: =Totals!B1 -> ESTIMATING SHEET VERSION 8.6 | G1: Salesman: | H1: =Totals!H1 -> 0 | L1: 1 | N1: <- 1=Page Used, 0=Page not used
B2: Job Name: | C2: =Totals!C2 -> 0 | G2: Estimator: | H2: =Totals!H2 -> 0 | L2: =Totals!L2 -> 0
B3: Part Number | D3: QTY. | E3: MATERIAL DESCRIPTON | H3: LIST $ | J3: # of Contrs | K3: # of Points | M3: TOTAL | R3: Electrical Price Check | V3: Tech | Z3: Graphics | AD3: Programming
D5: 0 | E5: VAV Boxes w Heat | F5: Option | I5: #/unit | N5: 1 | O5: Pts/VAV | P5: =D5*N5 -> 0 | Q5: points | R5: =P5*S5 -> 0 | S5: 550 | T5: per VAV | V5: =P5*W5 -> 0 | W5: 1 | X5: per VAV | Z5: =P5*AA5 -> 0 | AA5: 0.25 | AB5: per VAV | AD5: =P5*AE5 -> 0 | AE5: 0.25 | AF5: per VAV
A6: =E6&F6 -> ControllerOptimizer BACnet MSTP VAV Cntr w Act & VP, Bluetooth, 7 UIO, 5 SSR | B6: =IF(E6="","",VLOOKUP(A6,'Parts List'!A:E,5,FALSE)) -> VAA-VA75MB24NMC | D6: =$D$5*I6 -> 0 | E6: Controller | F6: Optimizer BACnet MSTP VAV Cntr w Act & VP, Bluetooth, 7 UIO, 5 SSR | H6: =IF(E6="","",VLOOKUP(A6,'Parts List'!A:F,6,FALSE)) -> 281.3558 | I6: 1 | J6: =D6 -> 0 | K6: =D6*70 -> 0 | M6: =IF(H6="","",D6*H6) -> 0
A7: =E7&F7 -> Temp SensorTR100 Space with LCD | B7: =IF(E7="","",VLOOKUP(A7,'Parts List'!A:E,5,FALSE)) -> TR100-T-G | D7: =$D$5*I7 -> 0 | E7: Temp Sensor | F7: TR100 Space with LCD | H7: =IF(E7="","",VLOOKUP(A7,'Parts List'!A:F,6,FALSE)) -> 128.71265 | I7: 1 | M7: =IF(H7="","",D7*H7) -> 0
A8: =E8&F8 -> Temp SensorDuct Insertion Sensor | B8: =IF(E8="","",VLOOKUP(A8,'Parts List'!A:E,5,FALSE)) -> C7041B2005 | D8: =$D$5*I8 -> 0 | E8: Temp Sensor | F8: Duct Insertion Sensor | H8: =IF(E8="","",VLOOKUP(A8,'Parts List'!A:F,6,FALSE)) -> 23.18855 | I8: 1 | M8: =IF(H8="","",D8*H8) -> 0
A9: =E9&F9 -> Current SwDigital Status Switch | B9: =IF(E9="","",VLOOKUP(A9,'Parts List'!A:E,5,FALSE)) -> H600 | D9: =$D$5*I9 -> 0 | E9: Current Sw | F9: Digital Status Switch | H9: =IF(E9="","",VLOOKUP(A9,'Parts List'!A:F,6,FALSE)) -> 31.43 | I9: 0 | M9: =IF(H9="","",D9*H9) -> 0
A10: =E10&F10 -> RelayRIB Pilot Relay | B10: =IF(E10="","",VLOOKUP(A10,'Parts List'!A:E,5,FALSE)) -> RIBU1C | D10: =$D$5*I10 -> 0 | E10: Relay | F10: RIB Pilot Relay | H10: =IF(E10="","",VLOOKUP(A10,'Parts List'!A:F,6,FALSE)) -> 14.36 | I10: 0 | M10: =IF(H10="","",D10*H10) -> 0
A11: =E11&F11 -> VAV HW Valve 2W & 3-way NSR | B11: =IF(E11="","",VLOOKUP(A11,'Parts List'!A:E,5,FALSE)) -> N/A | D11: =$D$5*I11 -> 0 | E11: VAV HW Valve 2W & 3-way NSR | H11: 150 | I11: 0 | M11: =IF(H11="","",D11*H11) -> 0
A12: =E12&F12 -> Air Flow MonitorRetrofit Flow Ring for VAV Boxes | B12: =IF(E12="","",VLOOKUP(A12,'Parts List'!A:E,5,FALSE)) -> 36FMI | D12: =$D$5*I12 -> 0 | E12: Air Flow Monitor | F12: Retrofit Flow Ring for VAV Boxes | H12: =IF(E12="","",VLOOKUP(A12,'Parts List'!A:F,6,FALSE)) -> 95 | I12: 0 | M12: =IF(H12="","",D12*H12) -> 0
B13: =IF(E13="","",VLOOKUP(A13,'Parts List'!A:E,5,FALSE)) | H13: =IF(E13="","",VLOOKUP(A13,'Parts List'!A:F,6,FALSE)) | M13: =IF(H13="","",D13*H13)
A15: =E15&F15 -> Cooling Only VAV Boxes | D15: 0 | E15: Cooling Only VAV Boxes | I15: #/unit | N15: 1 | O15: Pts/VAV | P15: =D15*N15 -> 0 | Q15: points | R15: =P15*S15 -> 0 | S15: 550 | T15: per VAV | V15: =P15*W15 -> 0 | W15: 1 | X15: per VAV | Z15: =P15*AA15 -> 0 | AA15: 0.25 | AB15: per VAV | AD15: =P15*AE15 -> 0 | AE15: 0.25 | AF15: per VAV
A16: =E16&F16 -> ControllerOptimizer BACnet MSTP VAV Cntr w Act & VP, Bluetooth, 7 UIO, 5 SSR | B16: =IF(E16="","",VLOOKUP(A16,'Parts List'!A:E,5,FALSE)) -> VAA-VA75MB24NMC | D16: =$D$15*I16 -> 0 | E16: Controller | F16: Optimizer BACnet MSTP VAV Cntr w Act & VP, Bluetooth, 7 UIO, 5 SSR | H16: =IF(E16="","",VLOOKUP(A16,'Parts List'!A:F,6,FALSE)) -> 281.3558 | I16: 1 | J16: =D16 -> 0 | K16: =D16*70 -> 0 | M16: =IF(H16="","",D16*H16) -> 0
A17: =E17&F17 -> Temp SensorTR100 Space with LCD | B17: =IF(E17="","",VLOOKUP(A17,'Parts List'!A:E,5,FALSE)) -> TR100-T-G | D17: =$D$15*I17 -> 0 | E17: Temp Sensor | F17: TR100 Space with LCD | H17: =IF(E17="","",VLOOKUP(A17,'Parts List'!A:F,6,FALSE)) -> 128.71265 | I17: 1 | M17: =IF(H17="","",D17*H17) -> 0
A18: =E18&F18 -> Transformer40 VA | B18: =IF(E18="","",VLOOKUP(A18,'Parts List'!A:E,5,FALSE)) -> TR40VA001 | D18: =$D$15*I18 -> 0 | E18: Transformer | F18: 40 VA | H18: =IF(E18="","",VLOOKUP(A18,'Parts List'!A:F,6,FALSE)) -> 17.76 | I18: 0 | M18: =IF(H18="","",D18*H18) -> 0
A19: =E19&F19 -> Air Flow MonitorRetrofit Flow Ring for VAV Boxes | B19: =IF(E19="","",VLOOKUP(A19,'Parts List'!A:E,5,FALSE)) -> 36FMI | D19: =$D$15*I19 -> 0 | E19: Air Flow Monitor | F19: Retrofit Flow Ring for VAV Boxes | H19: =IF(E19="","",VLOOKUP(A19,'Parts List'!A:F,6,FALSE)) -> 95 | I19: 0 | M19: =IF(H19="","",D19*H19) -> 0
B20: =IF(E20="","",VLOOKUP(A20,'Parts List'!A:E,5,FALSE)) | H20: =IF(E20="","",VLOOKUP(A20,'Parts List'!A:F,6,FALSE)) | M20: =IF(H20="","",D20*H20)
D23: 0 | E23: Supply Air Boxes - CRC/Phoenix LV Wiring and Integration | I23: #/unit | N23: 1 | O23: Pts/VAV | P23: =D23*N23 -> 0 | Q23: points | R23: =P23*S23 -> 0 | S23: 750 | T23: per VAV | V23: =P23*W23 -> 0 | W23: 1 | X23: per VAV | Z23: =P23*AA23 -> 0 | AA23: 0.25 | AB23: per VAV | AD23: =P23*AE23 -> 0 | AE23: 0.25 | AF23: per VAV
A24: =E24&F24 | B24: =IF(E24="","",VLOOKUP(A24,'[2]Parts List'!A:E,5,FALSE)) | D24: =$D$23*I24 -> 0 | H24: =IF(E24="","",VLOOKUP(A24,'[2]Parts List'!A:F,6,FALSE)) | I24: 1 | J24: =D24 -> 0 | K24: =D24*50 -> 0 | M24: =IF(H24="","",D24*H24)
D27: 0 | E27: Exhaust Air Boxes - CRC/Phoenix LV Wiring and Integration | I27: #/unit | N27: 1 | O27: Pts/VAV | P27: =D27*N27 -> 0 | Q27: points | R27: =P27*S27 -> 0 | S27: 750 | T27: per VAV | V27: =P27*W27 -> 0 | W27: 1 | X27: per VAV | Z27: =P27*AA27 -> 0 | AA27: 0.25 | AB27: per VAV | AD27: =P27*AE27 -> 0 | AE27: 0.25 | AF27: per VAV
A28: =E28&F28 | B28: =IF(E28="","",VLOOKUP(A28,'[2]Parts List'!A:E,5,FALSE)) | D28: =$D$27*I28 -> 0 | H28: =IF(E28="","",VLOOKUP(A28,'[2]Parts List'!A:F,6,FALSE)) | I28: 1 | M28: =IF(H28="","",D28*H28)
D31: 0 | E31: Return Air Boxes - CRC/Phoenix LV Wiring and Integration | I31: #/unit | N31: 1 | O31: Pts/VAV | P31: =D31*N31 -> 0 | Q31: points | R31: =P31*S31 -> 0 | S31: 750 | T31: per VAV | V31: =P31*W31 -> 0 | W31: 1 | X31: per VAV | Z31: =P31*AA31 -> 0 | AA31: 0.25 | AB31: per VAV | AD31: =P31*AE31 -> 0 | AE31: 0.25 | AF31: per VAV
A32: =E32&F32 | B32: =IF(E32="","",VLOOKUP(A32,'[2]Parts List'!A:E,5,FALSE)) | D32: =$D$31*I32 -> 0 | H32: =IF(E32="","",VLOOKUP(A32,'[2]Parts List'!A:F,6,FALSE)) | I32: 1 | M32: =IF(H32="","",D32*H32)
D35: 0 | E35: OR Room Pressure Monitors - CRC/Phoenix LV Wiring and Integration | I35: #/unit | N35: 1 | O35: Pts/VAV | P35: =D35*N35 -> 0 | Q35: points | R35: =P35*S35 -> 0 | S35: 750 | T35: per VAV | V35: =P35*W35 -> 0 | W35: 1 | X35: per VAV | Z35: =P35*AA35 -> 0 | AA35: 0.25 | AB35: per VAV | AD35: =P35*AE35 -> 0 | AE35: 0.25 | AF35: per VAV
A36: =E36&F36 | B36: =IF(E36="","",VLOOKUP(A36,'[2]Parts List'!A:E,5,FALSE)) | D36: =$D$35*I36 -> 0 | H36: =IF(E36="","",VLOOKUP(A36,'[2]Parts List'!A:F,6,FALSE)) | I36: 1 | M36: =IF(H36="","",D36*H36)
A40: =E40&F40 -> Cooling Only VAV Box Transformers | D40: 0 | E40: Cooling Only VAV Box Transformers | I40: #/unit | N40: =SUM(I41:I43) -> 0 | O40: Pts/Unit | P40: =D40*N40 -> 0 | Q40: points | R40: =P40*S40 -> 0 | S40: 550 | T40: per Unit | V40: =P40*W40 -> 0 | W40: 0 | X40: per unit | Z40: =D40*AA40 -> 0 | AA40: 0 | AB40: per unit | AD40: =D40*AE40 -> 0 | AE40: 0 | AF40: per unit
A41: =E41&F41 -> Transformer(3) - 100 VA w Enclosure | B41: =IF(E41="","",VLOOKUP(A41,'Parts List'!A:E,5,FALSE)) -> PSH300A | D41: =$D$40*I41 -> 0 | E41: Transformer | F41: (3) - 100 VA w Enclosure | H41: =IF(E41="","",VLOOKUP(A41,'Parts List'!A:F,6,FALSE)) -> 314.8 | I41: 0 | M41: =IF(H41="","",D41*H41) -> 0
A42: =E42&F42 -> Transformer(5) - 100 VA w Enclosure | B42: =IF(E42="","",VLOOKUP(A42,'Parts List'!A:E,5,FALSE)) -> PSH500A | D42: =$D$40*I42 -> 0 | E42: Transformer | F42: (5) - 100 VA w Enclosure | H42: =IF(E42="","",VLOOKUP(A42,'Parts List'!A:F,6,FALSE)) -> 430.65 | I42: 0 | M42: =IF(H42="","",D42*H42) -> 0
A43: =E43&F43 | B43: =IF(E43="","",VLOOKUP(A43,'Parts List'!A:E,5,FALSE)) | D43: =$D$40*I43 -> 0 | H43: =IF(E43="","",VLOOKUP(A43,'Parts List'!A:F,6,FALSE)) | I43: 0 | M43: =IF(H43="","",D43*H43)
B44: =IF(E44="","",VLOOKUP(A44,'Parts List'!A:E,5,FALSE)) | H44: =IF(E44="","",VLOOKUP(A44,'Parts List'!A:F,6,FALSE)) | M44: =IF(H44="","",D44*H44)
A46: =E46&F46 -> VAV Air Handling Unit | D46: 0 | E46: VAV Air Handling Unit | I46: #/unit | N46: =SUM(I57:I73)+I52 -> 1 | O46: Pts/Unit | P46: =D46*N46 -> 0 | Q46: points | R46: =P46*S46 -> 0 | S46: 350 | T46: per point | V46: =P46*W46 -> 0 | W46: 1 | X46: per point | Z46: =D46*AA46 -> 0 | AA46: 4 | AB46: per unit | AD46: =D46*AE46 -> 0 | AE46: 6 | AF46: per unit
A47: =E47&F47 -> ControllerOptimizer Plant Cntr, 1 IP, 3 Ethernet Switched+4 RS485 Ports | B47: =IF(E47="","",VLOOKUP(A47,'Parts List'!A:E,5,FALSE)) -> N-ADV-134-H-C | D47: =$D$46*I47 -> 0 | E47: Controller | F47: Optimizer Plant Cntr, 1 IP, 3 Ethernet Switched+4 RS485 Ports | H47: =IF(E47="","",VLOOKUP(A47,'Parts List'!A:F,6,FALSE)) -> 875.1457 | I47: 0 | J47: =D47 -> 0 | K47: =D47*70 -> 0 | M47: =IF(H47="","",D47*H47) -> 0
A48: =E48&F48 -> Optimizer License with 18 Month SMA | B48: =IF(E48="","",VLOOKUP(A48,'Parts List'!A:E,5,FALSE)) -> Select Option | D48: =$D$46*I48 -> 0 | E48: Optimizer License with 18 Month SMA | H48: =IF(E48="","",VLOOKUP(A48,'Parts List'!A:F,6,FALSE)) -> 0 | I48: 0 | J48: =D48 -> 0 | K48: =D48*70 -> 0 | M48: =IF(H48="","",D48*H48) -> 0
A49: =E49&F49 -> I/O ModuleOptimzer Unitary Cntr 5-UI, 5-DI, 4-AO, 4-DO I/O Module | B49: =IF(E49="","",VLOOKUP(A49,'Parts List'!A:E,5,FALSE)) -> ISMA-B-MIX18 | D49: =$D$46*I49 -> 0 | E49: I/O Module | F49: Optimzer Unitary Cntr 5-UI, 5-DI, 4-AO, 4-DO I/O Module | H49: =IF(E49="","",VLOOKUP(A49,'Parts List'!A:F,6,FALSE)) -> 338.81 | I49: 0 | M49: =IF(H49="","",D49*H49) -> 0
A50: =E50&F50 -> Phoenix Controller Core License | B50: =IF(E50="","",VLOOKUP(A50,'Parts List'!A:E,5,FALSE)) -> Select Option | D50: =$D$46*I50 -> 0 | E50: Phoenix Controller Core License | H50: =IF(E50="","",VLOOKUP(A50,'Parts List'!A:F,6,FALSE)) -> 0 | I50: 0 | M50: =IF(H50="","",D50*H50) -> 0
